Workbook

Sheet Wellness preferences
A1: Test ID | B1: Member name | C1: Goal used for test | D1: Activity frequency | E1: Time exercising | F1: Smoking | G1: Alcohol | H1: Where they work | I1: Sitting hours | J1: Stress level | K1: Sleep hours | L1: Diet | M1: Number of meals | N1: Meals at home | O1: Takeout | P1: Weak, fatigued or sluggish | Q1: Digestive discomforts | R1: Calorie awareness | S1: Nutrition and exercise | T1: Look and feel | U1: Goal seriousness | V1: Profile last updated
A2: ='Raw IDs'!A2 -> m1 | B2: =INDEX('ID key'!$C$2:$C$13,MATCH($A2,'ID key'!$A$2:$A$13,0))&" "&INDEX('ID key'!$D$2:$D$13,MATCH($A2,'ID key'!$A$2:$A$13,0)) -> Levent Soydaner | C2: =IFERROR(INDEX('Member goals'!$E$2:$E$26,MATCH($A2&"|1",'Member goals'!$G$2:$G$26,0)),"Not provided") -> Improve cardio performance | D2: =IF('Raw IDs'!B2="","Not answered",IFERROR(INDEX(Options!$C$2:$C$55,MATCH("freq|"&'Raw IDs'!B2,Options!$D$2:$D$55,0)),"Not set ("&'Raw IDs'!B2&")")) -> 3-4 times / week | E2: =IF('Raw IDs'!C2="","Not answered",IFERROR(INDEX(Options!$C$2:$C$55,MATCH("time|"&'Raw IDs'!C2,Options!$D$2:$D$55,0)),"Not set ("&'Raw IDs'!C2&")")) -> 1-3 years | F2: =IF('Raw IDs'!D2="","Not answered",IFERROR(INDEX(Options!$C$2:$C$55,MATCH("smoke|"&'Raw IDs'!D2,Options!$D$2:$D$55,0)),"Not set ("&'Raw IDs'!D2&")")) -> No | G2: =IF('Raw IDs'!E2="","Not answered",IFERROR(INDEX(Options!$C$2:$C$55,MATCH("alcohol|"&'Raw IDs'!E2,Options!$D$2:$D$55,0)),"Not set ("&'Raw IDs'!E2&")")) -> Occasionally | H2: =IF('Raw IDs'!F2="","Not answered",IFERROR(INDEX(Options!$C$2:$C$55,MATCH("work|"&'Raw IDs'!F2,Options!$D$2:$D$55,0)),"Not set ("&'Raw IDs'!F2&")")) -> Not set (0) | I2: =IF('Raw IDs'!G2="","Not answered",'Raw IDs'!G2) -> Not answered | J2: =IF('Raw IDs'!H2="","Not answered",IFERROR(INDEX(Options!$C$2:$C$55,MATCH("stress|"&'Raw IDs'!H2,Options!$D$2:$D$55,0)),"Not set ("&'Raw IDs'!H2&")")) -> Manageable | K2: =IF('Raw IDs'!I2="","Not answered",IFERROR(INDEX(Options!$C$2:$C$55,MATCH("sleep|"&'Raw IDs'!I2,Options!$D$2:$D$55,0)),"Not set ("&'Raw IDs'!I2&")")) -> 7 or more | L2: =IF('Raw IDs'!J2="","Not answered",IFERROR(INDEX(Options!$C$2:$C$55,MATCH("diet|"&'Raw IDs'!J2,Options!$D$2:$D$55,0)),"Not set ("&'Raw IDs'!J2&")")) -> Balanced | M2: =IF('Raw IDs'!K2="","Not answered",IF('Raw IDs'!K2=0,"Not set (0)",'Raw IDs'!K2)) -> Not set (0) | N2: =IF('Raw IDs'!L2="","Not answered",IFERROR(INDEX(Options!$C$2:$C$55,MATCH("home|"&'Raw IDs'!L2,Options!$D$2:$D$55,0)),"Not set ("&'Raw IDs'!L2&")")) -> Not answered | O2: =IF('Raw IDs'!M2="","Not answered",IFERROR(INDEX(Options!$C$2:$C$55,MATCH("takeout|"&'Raw IDs'!M2,Options!$D$2:$D$55,0)),"Not set ("&'Raw IDs'!M2&")")) -> Not answered | P2: =IF('Raw IDs'!N2="","Not answered",IFERROR(INDEX(Options!$C$2:$C$55,MATCH("yesno|"&'Raw IDs'!N2,Options!$D$2:$D$55,0)),"Not set ("&'Raw IDs'!N2&")")) -> Yes | Q2: =IF('Raw IDs'!O2="","Not answered",IFERROR(INDEX(Options!$C$2:$C$55,MATCH("yesno|"&'Raw IDs'!O2,Options!$D$2:$D$55,0)),"Not set ("&'Raw IDs'!O2&")")) -> Yes | R2: =IF('Raw IDs'!P2="","Not answered",IFERROR(INDEX(Options!$C$2:$C$55,MATCH("yesno|"&'Raw IDs'!P2,Options!$D$2:$D$55,0)),"Not set ("&'Raw IDs'!P2&")")) -> Yes | S2: =IF('Raw IDs'!Q2="","Not answered",IFERROR(INDEX(Options!$C$2:$C$55,MATCH("yesno|"&'Raw IDs'!Q2,Options!$D$2:$D$55,0)),"Not set ("&'Raw IDs'!Q2&")")) -> Yes | T2: =IF('Raw IDs'!R2="","Not answered",IFERROR(INDEX(Options!$C$2:$C$55,MATCH("yesno|"&'Raw IDs'!R2,Options!$D$2:$D$55,0)),"Not set ("&'Raw IDs'!R2&")")) -> Yes | U2: =IF('Raw IDs'!S2="","Not answered",IFERROR(INDEX(Options!$C$2:$C$55,MATCH("seriousness|"&'Raw IDs'!S2,Options!$D$2:$D$55,0)),"Not set ("&'Raw IDs'!S2&")")) -> 5 | V2: ='Raw IDs'!T2 -> 2025-07-18
A3: ='Raw IDs'!A3 -> m2 | B3: =INDEX('ID key'!$C$2:$C$13,MATCH($A3,'ID key'!$A$2:$A$13,0))&" "&INDEX('ID key'!$D$2:$D$13,MATCH($A3,'ID key'!$A$2:$A$13,0)) -> Veronika Masarskaya | C3: =IFERROR(INDEX('Member goals'!$E$2:$E$26,MATCH($A3&"|1",'Member goals'!$G$2:$G$26,0)),"Not provided") -> Weight loss | D3: =IF('Raw IDs'!B3="","Not answered",IFERROR(INDEX(Options!$C$2:$C$55,MATCH("freq|"&'Raw IDs'!B3,Options!$D$2:$D$55,0)),"Not set ("&'Raw IDs'!B3&")")) -> 1-2 times / week | E3: =IF('Raw IDs'!C3="","Not answered",IFERROR(INDEX(Options!$C$2:$C$55,MATCH("time|"&'Raw IDs'!C3,Options!$D$2:$D$55,0)),"Not set ("&'Raw IDs'!C3&")")) -> 3+ years | F3: =IF('Raw IDs'!D3="","Not answered",IFERROR(INDEX(Options!$C$2:$C$55,MATCH("smoke|"&'Raw IDs'!D3,Options!$D$2:$D$55,0)),"Not set ("&'Raw IDs'!D3&")")) -> No | G3: =IF('Raw IDs'!E3="","Not answered",IFERROR(INDEX(Options!$C$2:$C$55,MATCH("alcohol|"&'Raw IDs'!E3,Options!$D$2:$D$55,0)),"Not set ("&'Raw IDs'!E3&")")) -> Never | H3: =IF('Raw IDs'!F3="","Not answered",IFERROR(INDEX(Options!$C$2:$C$55,MATCH("work|"&'Raw IDs'!F3,Options!$D$2:$D$55,0)),"Not set ("&'Raw IDs'!F3&")")) -> Not set (0) | I3: =IF('Raw IDs'!G3="","Not answered",'Raw IDs'!G3) -> Not answered | J3: =IF('Raw IDs'!H3="","Not answered",IFERROR(INDEX(Options!$C$2:$C$55,MATCH("stress|"&'Raw IDs'!H3,Options!$D$2:$D$55,0)),"Not set ("&'Raw IDs'!H3&")")) -> Manageable | K3: =IF('Raw IDs'!I3="","Not answered",IFERROR(INDEX(Options!$C$2:$C$55,MATCH("sleep|"&'Raw IDs'!I3,Options!$D$2:$D$55,0)),"Not set ("&'Raw IDs'!I3&")")) -> 7 or more | L3: =IF('Raw IDs'!J3="","Not answered",IFERROR(INDEX(Options!$C$2:$C$55,MATCH("diet|"&'Raw IDs'!J3,Options!$D$2:$D$55,0)),"Not set ("&'Raw IDs'!J3&")")) -> Balanced | M3: =IF('Raw IDs'!K3="","Not answered",IF('Raw IDs'!K3=0,"Not set (0)",'Raw IDs'!K3)) -> Not set (0) | N3: =IF('Raw IDs'!L3="","Not answered",IFERROR(INDEX(Options!$C$2:$C$55,MATCH("home|"&'Raw IDs'!L3,Options!$D$2:$D$55,0)),"Not set ("&'Raw IDs'!L3&")")) -> Not answered | O3: =IF('Raw IDs'!M3="","Not answered",IFERROR(INDEX(Options!$C$2:$C$55,MATCH("takeout|"&'Raw IDs'!M3,Options!$D$2:$D$55,0)),"Not set ("&'Raw IDs'!M3&")")) -> Not answered | P3: =IF('Raw IDs'!N3="","Not answered",IFERROR(INDEX(Options!$C$2:$C$55,MATCH("yesno|"&'Raw IDs'!N3,Options!$D$2:$D$55,0)),"Not set ("&'Raw IDs'!N3&")")) -> No | Q3: =IF('Raw IDs'!O3="","Not answered",IFERROR(INDEX(Options!$C$2:$C$55,MATCH("yesno|"&'Raw IDs'!O3,Options!$D$2:$D$55,0)),"Not set ("&'Raw IDs'!O3&")")) -> No | R3: =IF('Raw IDs'!P3="","Not answered",IFERROR(INDEX(Options!$C$2:$C$55,MATCH("yesno|"&'Raw IDs'!P3,Options!$D$2:$D$55,0)),"Not set ("&'Raw IDs'!P3&")")) -> Yes | S3: =IF('Raw IDs'!Q3="","Not answered",IFERROR(INDEX(Options!$C$2:$C$55,MATCH("yesno|"&'Raw IDs'!Q3,Options!$D$2:$D$55,0)),"Not set ("&'Raw IDs'!Q3&")")) -> Yes | T3: =IF('Raw IDs'!R3="","Not answered",IFERROR(INDEX(Options!$C$2:$C$55,MATCH("yesno|"&'Raw IDs'!R3,Options!$D$2:$D$55,0)),"Not set ("&'Raw IDs'!R3&")")) -> Yes | U3: =IF('Raw IDs'!S3="","Not answered",IFERROR(INDEX(Options!$C$2:$C$55,MATCH("seriousness|"&'Raw IDs'!S3,Options!$D$2:$D$55,0)),"Not set ("&'Raw IDs'!S3&")")) -> Motivated | V3: ='Raw IDs'!T3 -> 2025-07-20
A4: ='Raw IDs'!A4 -> m3 | B4: =INDEX('ID key'!$C$2:$C$13,MATCH($A4,'ID key'!$A$2:$A$13,0))&" "&INDEX('ID key'!$D$2:$D$13,MATCH($A4,'ID key'!$A$2:$A$13,0)) -> Elen Kost | C4: =IFERROR(INDEX('Member goals'!$E$2:$E$26,MATCH($A4&"|1",'Member goals'!$G$2:$G$26,0)),"Not provided") -> Muscle tone | D4: =IF('Raw IDs'!B4="","Not answered",IFERROR(INDEX(Options!$C$2:$C$55,MATCH("freq|"&'Raw IDs'!B4,Options!$D$2:$D$55,0)),"Not set ("&'Raw IDs'!B4&")")) -> 3-4 times / week | E4: =IF('Raw IDs'!C4="","Not answered",IFERROR(INDEX(Options!$C$2:$C$55,MATCH("time|"&'Raw IDs'!C4,Options!$D$2:$D$55,0)),"Not set ("&'Raw IDs'!C4&")")) -> 3+ years | F4: =IF('Raw IDs'!D4="","Not answered",IFERROR(INDEX(Options!$C$2:$C$55,MATCH("smoke|"&'Raw IDs'!D4,Options!$D$2:$D$55,0)),"Not set ("&'Raw IDs'!D4&")")) -> No | G4: =IF('Raw IDs'!E4="","Not answered",IFERROR(INDEX(Options!$C$2:$C$55,MATCH("alcohol|"&'Raw IDs'!E4,Options!$D$2:$D$55,0)),"Not set ("&'Raw IDs'!E4&")")) -> Never | H4: =IF('Raw IDs'!F4="","Not answered",IFERROR(INDEX(Options!$C$2:$C$55,MATCH("work|"&'Raw IDs'!F4,Options!$D$2:$D$55,0)),"Not set ("&'Raw IDs'!F4&")")) -> Not set (0) | I4: =IF('Raw IDs'!G4="","Not answered",'Raw IDs'!G4) -> Not answered | J4: =IF('Raw IDs'!H4="","Not answered",IFERROR(INDEX(Options!$C$2:$C$55,MATCH("stress|"&'Raw IDs'!H4,Options!$D$2:$D$55,0)),"Not set ("&'Raw IDs'!H4&")")) -> Manageable | K4: =IF('Raw IDs'!I4="","Not answered",IFERROR(INDEX(Options!$C$2:$C$55,MATCH("sleep|"&'Raw IDs'!I4,Options!$D$2:$D$55,0)),"Not set ("&'Raw IDs'!I4&")")) -> 6 or less | L4: =IF('Raw IDs'!J4="","Not answered",IFERROR(INDEX(Options!$C$2:$C$55,MATCH("diet|"&'Raw IDs'!J4,Options!$D$2:$D$55,0)),"Not set ("&'Raw IDs'!J4&")")) -> Unhealthy | M4: =IF('Raw IDs'!K4="","Not answered",IF('Raw IDs'!K4=0,"Not set (0)",'Raw IDs'!K4)) -> 1 | N4: =IF('Raw IDs'!L4="","Not answered",IFERROR(INDEX(Options!$C$2:$C$55,MATCH("home|"&'Raw IDs'!L4,Options!$D$2:$D$55,0)),"Not set ("&'Raw IDs'!L4&")")) -> Not answered | O4: =IF('Raw IDs'!M4="","Not answered",IFERROR(INDEX(Options!$C$2:$C$55,MATCH("takeout|"&'Raw IDs'!M4,Options!$D$2:$D$55,0)),"Not set ("&'Raw IDs'!M4&")")) -> Not answered | P4: =IF('Raw IDs'!N4="","Not answered",IFERROR(INDEX(Options!$C$2:$C$55,MATCH("yesno|"&'Raw IDs'!N4,Options!$D$2:$D$55,0)),"Not set ("&'Raw IDs'!N4&")")) -> Yes | Q4: =IF('Raw IDs'!O4="","Not answered",IFERROR(INDEX(Options!$C$2:$C$55,MATCH("yesno|"&'Raw IDs'!O4,Options!$D$2:$D$55,0)),"Not set ("&'Raw IDs'!O4&")")) -> No | R4: =IF('Raw IDs'!P4="","Not answered",IFERROR(INDEX(Options!$C$2:$C$55,MATCH("yesno|"&'Raw IDs'!P4,Options!$D$2:$D$55,0)),"Not set ("&'Raw IDs'!P4&")")) -> No | S4: =IF('Raw IDs'!Q4="","Not answered",IFERROR(INDEX(Options!$C$2:$C$55,MATCH("yesno|"&'Raw IDs'!Q4,Options!$D$2:$D$55,0)),"Not set ("&'Raw IDs'!Q4&")")) -> Yes | T4: =IF('Raw IDs'!R4="","Not answered",IFERROR(INDEX(Options!$C$2:$C$55,MATCH("yesno|"&'Raw IDs'!R4,Options!$D$2:$D$55,0)),"Not set ("&'Raw IDs'!R4&")")) -> Yes | U4: =IF('Raw IDs'!S4="","Not answered",IFERROR(INDEX(Options!$C$2:$C$55,MATCH("seriousness|"&'Raw IDs'!S4,Options!$D$2:$D$55,0)),"Not set ("&'Raw IDs'!S4&")")) -> 4 | V4: ='Raw IDs'!T4 -> 2025-07-24
A5: ='Raw IDs'!A5 -> m4 | B5: =INDEX('ID key'!$C$2:$C$13,MATCH($A5,'ID key'!$A$2:$A$13,0))&" "&INDEX('ID key'!$D$2:$D$13,MATCH($A5,'ID key'!$A$2:$A$13,0)) -> Emma Arlemark | C5: =IFERROR(INDEX('Member goals'!$E$2:$E$26,MATCH($A5&"|1",'Member goals'!$G$2:$G$26,0)),"Not provided") -> Weight loss | D5: =IF('Raw IDs'!B5="","Not answered",IFERROR(INDEX(Options!$C$2:$C$55,MATCH("freq|"&'Raw IDs'!B5,Options!$D$2:$D$55,0)),"Not set ("&'Raw IDs'!B5&")")) -> 1-2 times / week | E5: =IF('Raw IDs'!C5="","Not answered",IFERROR(INDEX(Options!$C$2:$C$55,MATCH("time|"&'Raw IDs'!C5,Options!$D$2:$D$55,0)),"Not set ("&'Raw IDs'!C5&")")) -> Less than a year | F5: =IF('Raw IDs'!D5="","Not answered",IFERROR(INDEX(Options!$C$2:$C$55,MATCH("smoke|"&'Raw IDs'!D5,Options!$D$2:$D$55,0)),"Not set ("&'Raw IDs'!D5&")")) -> Yes | G5: =IF('Raw IDs'!E5="","Not answered",IFERROR(INDEX(Options!$C$2:$C$55,MATCH("alcohol|"&'Raw IDs'!E5,Options!$D$2:$D$55,0)),"Not set ("&'Raw IDs'!E5&")")) -> Occasionally | H5: =IF('Raw IDs'!F5="","Not answered",IFERROR(INDEX(Options!$C$2:$C$55,MATCH("work|"&'Raw IDs'!F5,Options!$D$2:$D$55,0)),"Not set ("&'Raw IDs'!F5&")")) -> Not set (0) | I5: =IF('Raw IDs'!G5="","Not answered",'Raw IDs'!G5) -> Not answered | J5: =IF('Raw IDs'!H5="","Not answered",IFERROR(INDEX(Options!$C$2:$C$55,MATCH("stress|"&'Raw IDs'!H5,Options!$D$2:$D$55,0)),"Not set ("&'Raw IDs'!H5&")")) -> Manageable | K5: =IF('Raw IDs'!I5="","Not answered",IFERROR(INDEX(Options!$C$2:$C$55,MATCH("sleep|"&'Raw IDs'!I5,Options!$D$2:$D$55,0)),"Not set ("&'Raw IDs'!I5&")")) -> 6 or less | L5: =IF('Raw IDs'!J5="","Not answered",IFERROR(INDEX(Options!$C$2:$C$55,MATCH("diet|"&'Raw IDs'!J5,Options!$D$2:$D$55,0)),"Not set ("&'Raw IDs'!J5&")")) -> Balanced | M5: =IF('Raw IDs'!K5="","Not answered",IF('Raw IDs'!K5=0,"Not set (0)",'Raw IDs'!K5)) -> 2 | N5: =IF('Raw IDs'!L5="","Not answered",IFERROR(INDEX(Options!$C$2:$C$55,MATCH("home|"&'Raw IDs'!L5,Options!$D$2:$D$55,0)),"Not set ("&'Raw IDs'!L5&")")) -> Not answered | O5: =IF('Raw IDs'!M5="","Not answered",IFERROR(INDEX(Options!$C$2:$C$55,MATCH("takeout|"&'Raw IDs'!M5,Options!$D$2:$D$55,0)),"Not set ("&'Raw IDs'!M5&")")) -> Not answered | P5: =IF('Raw IDs'!N5="","Not answered",IFERROR(INDEX(Options!$C$2:$C$55,MATCH("yesno|"&'Raw IDs'!N5,Options!$D$2:$D$55,0)),"Not set ("&'Raw IDs'!N5&")")) -> Yes | Q5: =IF('Raw IDs'!O5="","Not answered",IFERROR(INDEX(Options!$C$2:$C$55,MATCH("yesno|"&'Raw IDs'!O5,Options!$D$2:$D$55,0)),"Not set ("&'Raw IDs'!O5&")")) -> No | R5: =IF('Raw IDs'!P5="","Not answered",IFERROR(INDEX(Options!$C$2:$C$55,MATCH("yesno|"&'Raw IDs'!P5,Options!$D$2:$D$55,0)),"Not set ("&'Raw IDs'!P5&")")) -> No | S5: =IF('Raw IDs'!Q5="","Not answered",IFERROR(INDEX(Options!$C$2:$C$55,MATCH("yesno|"&'Raw IDs'!Q5,Options!$D$2:$D$55,0)),"Not set ("&'Raw IDs'!Q5&")")) -> No | T5: =IF('Raw IDs'!R5="","Not answered",IFERROR(INDEX(Options!$C$2:$C$55,MATCH("yesno|"&'Raw IDs'!R5,Options!$D$2:$D$55,0)),"Not set ("&'Raw IDs'!R5&")")) -> No | U5: =IF('Raw IDs'!S5="","Not answered",IFERROR(INDEX(Options!$C$2:$C$55,MATCH("seriousness|"&'Raw IDs'!S5,Options!$D$2:$D$55,0)),"Not set ("&'Raw IDs'!S5&")")) -> 4 | V5: ='Raw IDs'!T5 -> 2025-07-27
A6: ='Raw IDs'!A6 -> m5 | B6: =INDEX('ID key'!$C$2:$C$13,MATCH($A6,'ID key'!$A$2:$A$13,0))&" "&INDEX('ID key'!$D$2:$D$13,MATCH($A6,'ID key'!$A$2:$A$13,0)) -> Ria Juma | C6: =IFERROR(INDEX('Member goals'!$E$2:$E$26,MATCH($A6&"|1",'Member goals'!$G$2:$G$26,0)),"Not provided") -> Build strength | D6: =IF('Raw IDs'!B6="","Not answered",IFERROR(INDEX(Options!$C$2:$C$55,MATCH("freq|"&'Raw IDs'!B6,Options!$D$2:$D$55,0)),"Not set ("&'Raw IDs'!B6&")")) -> 3-4 times / week | E6: =IF('Raw IDs'!C6="","Not answered",IFERROR(INDEX(Options!$C$2:$C$55,MATCH("time|"&'Raw IDs'!C6,Options!$D$2:$D$55,0)),"Not set ("&'Raw IDs'!C6&")")) -> 3+ years | F6: =IF('Raw IDs'!D6="","Not answered",IFERROR(INDEX(Options!$C$2:$C$55,MATCH("smoke|"&'Raw IDs'!D6,Options!$D$2:$D$55,0)),"Not set ("&'Raw IDs'!D6&")")) -> No | G6: =IF('Raw IDs'!E6="","Not answered",IFERROR(INDEX(Options!$C$2:$C$55,MATCH("alcohol|"&'Raw IDs'!E6,Options!$D$2:$D$55,0)),"Not set ("&'Raw IDs'!E6&")")) -> Occasionally | H6: =IF('Raw IDs'!F6="","Not answered",IFERROR(INDEX(Options!$C$2:$C$55,MATCH("work|"&'Raw IDs'!F6,Options!$D$2:$D$55,0)),"Not set ("&'Raw IDs'!F6&")")) -> Not set (0) | I6: =IF('Raw IDs'!G6="","Not answered",'Raw IDs'!G6) -> Not answered | J6: =IF('Raw IDs'!H6="","Not answered",IFERROR(INDEX(Options!$C$2:$C$55,MATCH("stress|"&'Raw IDs'!H6,Options!$D$2:$D$55,0)),"Not set ("&'Raw IDs'!H6&")")) -> Manageable | K6: =IF('Raw IDs'!I6="","Not answered",IFERROR(INDEX(Options!$C$2:$C$55,MATCH("sleep|"&'Raw IDs'!I6,Options!$D$2:$D$55,0)),"Not set ("&'Raw IDs'!I6&")")) -> 7 or more | L6: =IF('Raw IDs'!J6="","Not answered",IFERROR(INDEX(Options!$C$2:$C$55,MATCH("diet|"&'Raw IDs'!J6,Options!$D$2:$D$55,0)),"Not set ("&'Raw IDs'!J6&")")) -> Balanced | M6: =IF('Raw IDs'!K6="","Not answered",IF('Raw IDs'!K6=0,"Not set (0)",'Raw IDs'!K6)) -> 3 | N6: =IF('Raw IDs'!L6="","Not answered",IFERROR(INDEX(Options!$C$2:$C$55,MATCH("home|"&'Raw IDs'!L6,Options!$D$2:$D$55,0)),"Not set ("&'Raw IDs'!L6&")")) -> Not answered | O6: =IF('Raw IDs'!M6="","Not answered",IFERROR(INDEX(Options!$C$2:$C$55,MATCH("takeout|"&'Raw IDs'!M6,Options!$D$2:$D$55,0)),"Not set ("&'Raw IDs'!M6&")")) -> Not answered | P6: =IF('Raw IDs'!N6="","Not answered",IFERROR(INDEX(Options!$C$2:$C$55,MATCH("yesno|"&'Raw IDs'!N6,Options!$D$2:$D$55,0)),"Not set ("&'Raw IDs'!N6&")")) -> Yes | Q6: =IF('Raw IDs'!O6="","Not answered",IFERROR(INDEX(Options!$C$2:$C$55,MATCH("yesno|"&'Raw IDs'!O6,Options!$D$2:$D$55,0)),"Not set ("&'Raw IDs'!O6&")")) -> Yes | R6: =IF('Raw IDs'!P6="","Not answered",IFERROR(INDEX(Options!$C$2:$C$55,MATCH("yesno|"&'Raw IDs'!P6,Options!$D$2:$D$55,0)),"Not set ("&'Raw IDs'!P6&")")) -> No | S6: =IF('Raw IDs'!Q6="","Not answered",IFERROR(INDEX(Options!$C$2:$C$55,MATCH("yesno|"&'Raw IDs'!Q6,Options!$D$2:$D$55,0)),"Not set ("&'Raw IDs'!Q6&")")) -> Yes | T6: =IF('Raw IDs'!R6="","Not answered",IFERROR(INDEX(Options!$C$2:$C$55,MATCH("yesno|"&'Raw IDs'!R6,Options!$D$2:$D$55,0)),"Not set ("&'Raw IDs'!R6&")")) -> Yes | U6: =IF('Raw IDs'!S6="","Not answered",IFERROR(INDEX(Options!$C$2:$C$55,MATCH("seriousness|"&'Raw IDs'!S6,Options!$D$2:$D$55,0)),"Not set ("&'Raw IDs'!S6&")")) -> Motivated | V6: ='Raw IDs'!T6 -> 2025-07-27
A7: ='Raw IDs'!A7 -> m6 | B7: =INDEX('ID key'!$C$2:$C$13,MATCH($A7,'ID key'!$A$2:$A$13,0))&" "&INDEX('ID key'!$D$2:$D$13,MATCH($A7,'ID key'!$A$2:$A$13,0)) -> Maria Costanzo | C7: =IFERROR(INDEX('Member goals'!$E$2:$E$26,MATCH($A7&"|1",'Member goals'!$G$2:$G$26,0)),"Not provided") -> Muscle tone | D7: =IF('Raw IDs'!B7="","Not answered",IFERROR(INDEX(Options!$C$2:$C$55,MATCH("freq|"&'Raw IDs'!B7,Options!$D$2:$D$55,0)),"Not set ("&'Raw IDs'!B7&")")) -> 3-4 times / week | E7: =IF('Raw IDs'!C7="","Not answered",IFERROR(INDEX(Options!$C$2:$C$55,MATCH("time|"&'Raw IDs'!C7,Options!$D$2:$D$55,0)),"Not set ("&'Raw IDs'!C7&")")) -> 1-3 years | F7: =IF('Raw IDs'!D7="","Not answered",IFERROR(INDEX(Options!$C$2:$C$55,MATCH("smoke|"&'Raw IDs'!D7,Options!$D$2:$D$55,0)),"Not set ("&'Raw IDs'!D7&")")) -> Social / Occasional | G7: =IF('Raw IDs'!E7="","Not answered",IFERROR(INDEX(Options!$C$2:$C$55,MATCH("alcohol|"&'Raw IDs'!E7,Options!$D$2:$D$55,0)),"Not set ("&'Raw IDs'!E7&")")) -> Occasionally | H7: =IF('Raw IDs'!F7="","Not answered",IFERROR(INDEX(Options!$C$2:$C$55,MATCH("work|"&'Raw IDs'!F7,Options!$D$2:$D$55,0)),"Not set ("&'Raw IDs'!F7&")")) -> Not set (0) | I7: =IF('Raw IDs'!G7="","Not answered",'Raw IDs'!G7) -> Not answered | J7: =IF('Raw IDs'!H7="","Not answered",IFERROR(INDEX(Options!$C$2:$C$55,MATCH("stress|"&'Raw IDs'!H7,Options!$D$2:$D$55,0)),"Not set ("&'Raw IDs'!H7&")")) -> High | K7: =IF('Raw IDs'!I7="","Not answered",IFERROR(INDEX(Options!$C$2:$C$55,MATCH("sleep|"&'Raw IDs'!I7,Options!$D$2:$D$55,0)),"Not set ("&'Raw IDs'!I7&")")) -> 6 or less | L7: =IF('Raw IDs'!J7="","Not answered",IFERROR(INDEX(Options!$C$2:$C$55,MATCH("diet|"&'Raw IDs'!J7,Options!$D$2:$D$55,0)),"Not set ("&'Raw IDs'!J7&")")) -> Healthy | M7: =IF('Raw IDs'!K7="","Not answered",IF('Raw IDs'!K7=0,"Not set (0)",'Raw IDs'!K7)) -> Not set (0) | N7: =IF('Raw IDs'!L7="","Not answered",IFERROR(INDEX(Options!$C$2:$C$55,MATCH("home|"&'Raw IDs'!L7,Options!$D$2:$D$55,0)),"Not set ("&'Raw IDs'!L7&")")) -> Not answered | O7: =IF('Raw IDs'!M7="","Not answered",IFERROR(INDEX(Options!$C$2:$C$55,MATCH("takeout|"&'Raw IDs'!M7,Options!$D$2:$D$55,0)),"Not set ("&'Raw IDs'!M7&")")) -> Not answered | P7: =IF('Raw IDs'!N7="","Not answered",IFERROR(INDEX(Options!$C$2:$C$55,MATCH("yesno|"&'Raw IDs'!N7,Options!$D$2:$D$55,0)),"Not set ("&'Raw IDs'!N7&")")) -> No | Q7: =IF('Raw IDs'!O7="","Not answered",IFERROR(INDEX(Options!$C$2:$C$55,MATCH("yesno|"&'Raw IDs'!O7,Options!$D$2:$D$55,0)),"Not set ("&'Raw IDs'!O7&")")) -> Yes | R7: =IF('Raw IDs'!P7="","Not answered",IFERROR(INDEX(Options!$C$2:$C$55,MATCH("yesno|"&'Raw IDs'!P7,Options!$D$2:$D$55,0)),"Not set ("&'Raw IDs'!P7&")")) -> Yes | S7: =IF('Raw IDs'!Q7="","Not answered",IFERROR(INDEX(Options!$C$2:$C$55,MATCH("yesno|"&'Raw IDs'!Q7,Options!$D$2:$D$55,0)),"Not set ("&'Raw IDs'!Q7&")")) -> Yes | T7: =IF('Raw IDs'!R7="","Not answered",IFERROR(INDEX(Options!$C$2:$C$55,MATCH("yesno|"&'Raw IDs'!R7,Options!$D$2:$D$55,0)),"Not set ("&'Raw IDs'!R7&")")) -> No | U7: =IF('Raw IDs'!S7="","Not answered",IFERROR(INDEX(Options!$C$2:$C$55,MATCH("seriousness|"&'Raw IDs'!S7,Options!$D$2:$D$55,0)),"Not set ("&'Raw IDs'!S7&")")) -> Motivated | V7: ='Raw IDs'!T7 -> 2025-07-27
A8: ='Raw IDs'!A8 -> m7 | B8: =INDEX('ID key'!$C$2:$C$13,MATCH($A8,'ID key'!$A$2:$A$13,0))&" "&INDEX('ID key'!$D$2:$D$13,MATCH($A8,'ID key'!$A$2:$A$13,0)) -> Vinay Parmar | C8: =IFERROR(INDEX('Member goals'!$E$2:$E$26,MATCH($A8&"|1",'Member goals'!$G$2:$G$26,0)),"Not provided") -> Weight loss | D8: =IF('Raw IDs'!B8="","Not answered",IFERROR(INDEX(Options!$C$2:$C$55,MATCH("freq|"&'Raw IDs'!B8,Options!$D$2:$D$55,0)),"Not set ("&'Raw IDs'!B8&")")) -> 5-6 times / week | E8: =IF('Raw IDs'!C8="","Not answered",IFERROR(INDEX(Options!$C$2:$C$55,MATCH("time|"&'Raw IDs'!C8,Options!$D$2:$D$55,0)),"Not set ("&'Raw IDs'!C8&")")) -> 3+ years | F8: =IF('Raw IDs'!D8="","Not answered",IFERROR(INDEX(Options!$C$2:$C$55,MATCH("smoke|"&'Raw IDs'!D8,Options!$D$2:$D$55,0)),"Not set ("&'Raw IDs'!D8&")")) -> No | G8: =IF('Raw IDs'!E8="","Not answered",IFERROR(INDEX(Options!$C$2:$C$55,MATCH("alcohol|"&'Raw IDs'!E8,Options!$D$2:$D$55,0)),"Not set ("&'Raw IDs'!E8&")")) -> Occasionally | H8: =IF('Raw IDs'!F8="","Not answered",IFERROR(INDEX(Options!$C$2:$C$55,MATCH("work|"&'Raw IDs'!F8,Options!$D$2:$D$55,0)),"Not set ("&'Raw IDs'!F8&")")) -> Not set (0) | I8: =IF('Raw IDs'!G8="","Not answered",'Raw IDs'!G8) -> Not answered | J8: =IF('Raw IDs'!H8="","Not answered",IFERROR(INDEX(Options!$C$2:$C$55,MATCH("stress|"&'Raw IDs'!H8,Options!$D$2:$D$55,0)),"Not set ("&'Raw IDs'!H8&")")) -> Manageable | K8: =IF('Raw IDs'!I8="","Not answered",IFERROR(INDEX(Options!$C$2:$C$55,MATCH("sleep|"&'Raw IDs'!I8,Options!$D$2:$D$55,0)),"Not set ("&'Raw IDs'!I8&")")) -> 7 or more | L8: =IF('Raw IDs'!J8="","Not answered",IFERROR(INDEX(Options!$C$2:$C$55,MATCH("diet|"&'Raw IDs'!J8,Options!$D$2:$D$55,0)),"Not set ("&'Raw IDs'!J8&")")) -> Balanced | M8: =IF('Raw IDs'!K8="","Not answered",IF('Raw IDs'!K8=0,"Not set (0)",'Raw IDs'!K8)) -> Not set (0) | N8: =IF('Raw IDs'!L8="","Not answered",IFERROR(INDEX(Options!$C$2:$C$55,MATCH("home|"&'Raw IDs'!L8,Options!$D$2:$D$55,0)),"Not set ("&'Raw IDs'!L8&")")) -> Not answered | O8: =IF('Raw IDs'!M8="","Not answered",IFERROR(INDEX(Options!$C$2:$C$55,MATCH("takeout|"&'Raw IDs'!M8,Options!$D$2:$D$55,0)),"Not set ("&'Raw IDs'!M8&")")) -> Not answered | P8: =IF('Raw IDs'!N8="","Not answered",IFERROR(INDEX(Options!$C$2:$C$55,MATCH("yesno|"&'Raw IDs'!N8,Options!$D$2:$D$55,0)),"Not set ("&'Raw IDs'!N8&")")) -> No | Q8: =IF('Raw IDs'!O8="","Not answered",IFERROR(INDEX(Options!$C$2:$C$55,MATCH("yesno|"&'Raw IDs'!O8,Options!$D$2:$D$55,0)),"Not set ("&'Raw IDs'!O8&")")) -> No | R8: =IF('Raw IDs'!P8="","Not answered",IFERROR(INDEX(Options!$C$2:$C$55,MATCH("yesno|"&'Raw IDs'!P8,Options!$D$2:$D$55,0)),"Not set ("&'Raw IDs'!P8&")")) -> No | S8: =IF('Raw IDs'!Q8="","Not answered",IFERROR(INDEX(Options!$C$2:$C$55,MATCH("yesno|"&'Raw IDs'!Q8,Options!$D$2:$D$55,0)),"Not set ("&'Raw IDs'!Q8&")")) -> Yes | T8: =IF('Raw IDs'!R8="","Not answered",IFERROR(INDEX(Options!$C$2:$C$55,MATCH("yesno|"&'Raw IDs'!R8,Options!$D$2:$D$55,0)),"Not set ("&'Raw IDs'!R8&")")) -> No | U8: =IF('Raw IDs'!S8="","Not answered",IFERROR(INDEX(Options!$C$2:$C$55,MATCH("seriousness|"&'Raw IDs'!S8,Options!$D$2:$D$55,0)),"Not set ("&'Raw IDs'!S8&")")) -> Motivated | V8: ='Raw IDs'!T8 -> 2025-07-28
A9: ='Raw IDs'!A9 -> m8 | B9: =INDEX('ID key'!$C$2:$C$13,MATCH($A9,'ID key'!$A$2:$A$13,0))&" "&INDEX('ID key'!$D$2:$D$13,MATCH($A9,'ID key'!$A$2:$A$13,0)) -> Ruksana Hussain | C9: =IFERROR(INDEX('Member goals'!$E$2:$E$26,MATCH($A9&"|1",'Member goals'!$G$2:$G$26,0)),"Not provided") -> Weight loss | D9: =IF('Raw IDs'!B9="","Not answered",IFERROR(INDEX(Options!$C$2:$C$55,MATCH("freq|"&'Raw IDs'!B9,Options!$D$2:$D$55,0)),"Not set ("&'Raw IDs'!B9&")")) -> 5-6 times / week | E9: =IF('Raw IDs'!C9="","Not answered",IFERROR(INDEX(Options!$C$2:$C$55,MATCH("time|"&'Raw IDs'!C9,Options!$D$2:$D$55,0)),"Not set ("&'Raw IDs'!C9&")")) -> 3+ years | F9: =IF('Raw IDs'!D9="","Not answered",IFERROR(INDEX(Options!$C$2:$C$55,MATCH("smoke|"&'Raw IDs'!D9,Options!$D$2:$D$55,0)),"Not set ("&'Raw IDs'!D9&")")) -> No | G9: =IF('Raw IDs'!E9="","Not answered",IFERROR(INDEX(Options!$C$2:$C$55,MATCH("alcohol|"&'Raw IDs'!E9,Options!$D$2:$D$55,0)),"Not set ("&'Raw IDs'!E9&")")) -> Never | H9: =IF('Raw IDs'!F9="","Not answered",IFERROR(INDEX(Options!$C$2:$C$55,MATCH("work|"&'Raw IDs'!F9,Options!$D$2:$D$55,0)),"Not set ("&'Raw IDs'!F9&")")) -> Not set (0) | I9: =IF('Raw IDs'!G9="","Not answered",'Raw IDs'!G9) -> Not answered | J9: =IF('Raw IDs'!H9="","Not answered",IFERROR(INDEX(Options!$C$2:$C$55,MATCH("stress|"&'Raw IDs'!H9,Options!$D$2:$D$55,0)),"Not set ("&'Raw IDs'!H9&")")) -> Manageable | K9: =IF('Raw IDs'!I9="","Not answered",IFERROR(INDEX(Options!$C$2:$C$55,MATCH("sleep|"&'Raw IDs'!I9,Options!$D$2:$D$55,0)),"Not set ("&'Raw IDs'!I9&")")) -> 6 or less | L9: =IF('Raw IDs'!J9="","Not answered",IFERROR(INDEX(Options!$C$2:$C$55,MATCH("diet|"&'Raw IDs'!J9,Options!$D$2:$D$55,0)),"Not set ("&'Raw IDs'!J9&")")) -> Balanced | M9: =IF('Raw IDs'!K9="","Not answered",IF('Raw IDs'!K9=0,"Not set (0)",'Raw IDs'!K9)) -> 2 | N9: =IF('Raw IDs'!L9="","Not answered",IFERROR(INDEX(Options!$C$2:$C$55,MATCH("home|"&'Raw IDs'!L9,Options!$D$2:$D$55,0)),"Not set ("&'Raw IDs'!L9&")")) -> Not answered | O9: =IF('Raw IDs'!M9="","Not answered",IFERROR(INDEX(Options!$C$2:$C$55,MATCH("takeout|"&'Raw IDs'!M9,Options!$D$2:$D$55,0)),"Not set ("&'Raw IDs'!M9&")")) -> Not answered | P9: =IF('Raw IDs'!N9="","Not answered",IFERROR(INDEX(Options!$C$2:$C$55,MATCH("yesno|"&'Raw IDs'!N9,Options!$D$2:$D$55,0)),"Not set ("&'Raw IDs'!N9&")")) -> Yes | Q9: =IF('Raw IDs'!O9="","Not answered",IFERROR(INDEX(Options!$C$2:$C$55,MATCH("yesno|"&'Raw IDs'!O9,Options!$D$2:$D$55,0)),"Not set ("&'Raw IDs'!O9&")")) -> Yes | R9: =IF('Raw IDs'!P9="","Not answered",IFERROR(INDEX(Options!$C$2:$C$55,MATCH("yesno|"&'Raw IDs'!P9,Options!$D$2:$D$55,0)),"Not set ("&'Raw IDs'!P9&")")) -> No | S9: =IF('Raw IDs'!Q9="","Not answered",IFERROR(INDEX(Options!$C$2:$C$55,MATCH("yesno|"&'Raw IDs'!Q9,Options!$D$2:$D$55,0)),"Not set ("&'Raw IDs'!Q9&")")) -> No | T9: =IF('Raw IDs'!R9="","Not answered",IFERROR(INDEX(Options!$C$2:$C$55,MATCH("yesno|"&'Raw IDs'!R9,Options!$D$2:$D$55,0)),"Not set ("&'Raw IDs'!R9&")")) -> Yes | U9: =IF('Raw IDs'!S9="","Not answered",IFERROR(INDEX(Options!$C$2:$C$55,MATCH("seriousness|"&'Raw IDs'!S9,Options!$D$2:$D$55,0)),"Not set ("&'Raw IDs'!S9&")")) -> Motivated | V9: ='Raw IDs'!T9 -> 2025-07-29
A10: ='Raw IDs'!A10 -> m9 | B10: =INDEX('ID key'!$C$2:$C$13,MATCH($A10,'ID key'!$A$2:$A$13,0))&" "&INDEX('ID key'!$D$2:$D$13,MATCH($A10,'ID key'!$A$2:$A$13,0)) -> Asif Khokhar | C10: =IFERROR(INDEX('Member goals'!$E$2:$E$26,MATCH($A10&"|1",'Member goals'!$G$2:$G$26,0)),"Not provided") -> Not provided | D10: =IF('Raw IDs'!B10="","Not answered",IFERROR(INDEX(Options!$C$2:$C$55,MATCH("freq|"&'Raw IDs'!B10,Options!$D$2:$D$55,0)),"Not set ("&'Raw IDs'!B10&")")) -> 1-2 times / week | E10: =IF('Raw IDs'!C10="","Not answered",IFERROR(INDEX(Options!$C$2:$C$55,MATCH("time|"&'Raw IDs'!C10,Options!$D$2:$D$55,0)),"Not set ("&'Raw IDs'!C10&")")) -> 3+ years | F10: =IF('Raw IDs'!D10="","Not answered",IFERROR(INDEX(Options!$C$2:$C$55,MATCH("smoke|"&'Raw IDs'!D10,Options!$D$2:$D$55,0)),"Not set ("&'Raw IDs'!D10&")")) -> Social / Occasional | G10: =IF('Raw IDs'!E10="","Not answered",IFERROR(INDEX(Options!$C$2:$C$55,MATCH("alcohol|"&'Raw IDs'!E10,Options!$D$2:$D$55,0)),"Not set ("&'Raw IDs'!E10&")")) -> Never | H10: =IF('Raw IDs'!F10="","Not answered",IFERROR(INDEX(Options!$C$2:$C$55,MATCH("work|"&'Raw IDs'!F10,Options!$D$2:$D$55,0)),"Not set ("&'Raw IDs'!F10&")")) -> Not set (0) | I10: =IF('Raw IDs'!G10="","Not answered",'Raw IDs'!G10) -> Not answered | J10: =IF('Raw IDs'!H10="","Not answered",IFERROR(INDEX(Options!$C$2:$C$55,MATCH("stress|"&'Raw IDs'!H10,Options!$D$2:$D$55,0)),"Not set ("&'Raw IDs'!H10&")")) -> Manageable | K10: =IF('Raw IDs'!I10="","Not answered",IFERROR(INDEX(Options!$C$2:$C$55,MATCH("sleep|"&'Raw IDs'!I10,Options!$D$2:$D$55,0)),"Not set ("&'Raw IDs'!I10&")")) -> 6 or less | L10: =IF('Raw IDs'!J10="","Not answered",IFERROR(INDEX(Options!$C$2:$C$55,MATCH("diet|"&'Raw IDs'!J10,Options!$D$2:$D$55,0)),"Not set ("&'Raw IDs'!J10&")")) -> Balanced | M10: =IF('Raw IDs'!K10="","Not answered",IF('Raw IDs'!K10=0,"Not set (0)",'Raw IDs'!K10)) -> 3 | N10: =IF('Raw IDs'!L10="","Not answered",IFERROR(INDEX(Options!$C$2:$C$55,MATCH("home|"&'Raw IDs'!L10,Options!$D$2:$D$55,0)),"Not set ("&'Raw IDs'!L10&")")) -> Not answered | O10: =IF('Raw IDs'!M10="","Not answered",IFERROR(INDEX(Options!$C$2:$C$55,MATCH("takeout|"&'Raw IDs'!M10,Options!$D$2:$D$55,0)),"Not set ("&'Raw IDs'!M10&")")) -> Not answered | P10: =IF('Raw IDs'!N10="","Not answered",IFERROR(INDEX(Options!$C$2:$C$55,MATCH("yesno|"&'Raw IDs'!N10,Options!$D$2:$D$55,0)),"Not set ("&'Raw IDs'!N10&")")) -> No | Q10: =IF('Raw IDs'!O10="","Not answered",IFERROR(INDEX(Options!$C$2:$C$55,MATCH("yesno|"&'Raw IDs'!O10,Options!$D$2:$D$55,0)),"Not set ("&'Raw IDs'!O10&")")) -> No | R10: =IF('Raw IDs'!P10="","Not answered",IFERROR(INDEX(Options!$C$2:$C$55,MATCH("yesno|"&'Raw IDs'!P10,Options!$D$2:$D$55,0)),"Not set ("&'Raw IDs'!P10&")")) -> No | S10: =IF('Raw IDs'!Q10="","Not answered",IFERROR(INDEX(Options!$C$2:$C$55,MATCH("yesno|"&'Raw IDs'!Q10,Options!$D$2:$D$55,0)),"Not set ("&'Raw IDs'!Q10&")")) -> Yes | T10: =IF('Raw IDs'!R10="","Not answered",IFERROR(INDEX(Options!$C$2:$C$55,MATCH("yesno|"&'Raw IDs'!R10,Options!$D$2:$D$55,0)),"Not set ("&'Raw IDs'!R10&")")) -> Yes | U10: =IF('Raw IDs'!S10="","Not answered",IFERROR(INDEX(Options!$C$2:$C$55,MATCH("seriousness|"&'Raw IDs'!S10,Options!$D$2:$D$55,0)),"Not set ("&'Raw IDs'!S10&")")) -> Motivated | V10: ='Raw IDs'!T10 -> 2025-07-30
A11: ='Raw IDs'!A11 -> m10 | B11: =INDEX('ID key'!$C$2:$C$13,MATCH($A11,'ID key'!$A$2:$A$13,0))&" "&INDEX('ID key'!$D$2:$D$13,MATCH($A11,'ID key'!$A$2:$A$13,0)) -> Sadaf Hameed | C11: =IFERROR(INDEX('Member goals'!$E$2:$E$26,MATCH($A11&"|1",'Member goals'!$G$2:$G$26,0)),"Not provided") -> Not provided | D11: =IF('Raw IDs'!B11="","Not answered",IFERROR(INDEX(Options!$C$2:$C$55,MATCH("freq|"&'Raw IDs'!B11,Options!$D$2:$D$55,0)),"Not set ("&'Raw IDs'!B11&")")) -> 1-2 times / week | E11: =IF('Raw IDs'!C11="","Not answered",IFERROR(INDEX(Options!$C$2:$C$55,MATCH("time|"&'Raw IDs'!C11,Options!$D$2:$D$55,0)),"Not set ("&'Raw IDs'!C11&")")) -> Less than a year | F11: =IF('Raw IDs'!D11="","Not answered",IFERROR(INDEX(Options!$C$2:$C$55,MATCH("smoke|"&'Raw IDs'!D11,Options!$D$2:$D$55,0)),"Not set ("&'Raw IDs'!D11&")")) -> No | G11: =IF('Raw IDs'!E11="","Not answered",IFERROR(INDEX(Options!$C$2:$C$55,MATCH("alcohol|"&'Raw IDs'!E11,Options!$D$2:$D$55,0)),"Not set ("&'Raw IDs'!E11&")")) -> Never | H11: =IF('Raw IDs'!F11="","Not answered",IFERROR(INDEX(Options!$C$2:$C$55,MATCH("work|"&'Raw IDs'!F11,Options!$D$2:$D$55,0)),"Not set ("&'Raw IDs'!F11&")")) -> Not set (0) | I11: =IF('Raw IDs'!G11="","Not answered",'Raw IDs'!G11) -> Not answered | J11: =IF('Raw IDs'!H11="","Not answered",IFERROR(INDEX(Options!$C$2:$C$55,MATCH("stress|"&'Raw IDs'!H11,Options!$D$2:$D$55,0)),"Not set ("&'Raw IDs'!H11&")")) -> Manageable | K11: =IF('Raw IDs'!I11="","Not answered",IFERROR(INDEX(Options!$C$2:$C$55,MATCH("sleep|"&'Raw IDs'!I11,Options!$D$2:$D$55,0)),"Not set ("&'Raw IDs'!I11&")")) -> 6 or less | L11: =IF('Raw IDs'!J11="","Not answered",IFERROR(INDEX(Options!$C$2:$C$55,MATCH("diet|"&'Raw IDs'!J11,Options!$D$2:$D$55,0)),"Not set ("&'Raw IDs'!J11&")")) -> Balanced | M11: =IF('Raw IDs'!K11="","Not answered",IF('Raw IDs'!K11=0,"Not set (0)",'Raw IDs'!K11)) -> Not set (0) | N11: =IF('Raw IDs'!L11="","Not answered",IFERROR(INDEX(Options!$C$2:$C$55,MATCH("home|"&'Raw IDs'!L11,Options!$D$2:$D$55,0)),"Not set ("&'Raw IDs'!L11&")")) -> Not answered | O11: =IF('Raw IDs'!M11="","Not answered",IFERROR(INDEX(Options!$C$2:$C$55,MATCH("takeout|"&'Raw IDs'!M11,Options!$D$2:$D$55,0)),"Not set ("&'Raw IDs'!M11&")")) -> Not answered | P11: =IF('Raw IDs'!N11="","Not answered",IFERROR(INDEX(Options!$C$2:$C$55,MATCH("yesno|"&'Raw IDs'!N11,Options!$D$2:$D$55,0)),"Not set ("&'Raw IDs'!N11&")")) -> Yes | Q11: =IF('Raw IDs'!O11="","Not answered",IFERROR(INDEX(Options!$C$2:$C$55,MATCH("yesno|"&'Raw IDs'!O11,Options!$D$2:$D$55,0)),"Not set ("&'Raw IDs'!O11&")")) -> No | R11: =IF('Raw IDs'!P11="","Not answered",IFERROR(INDEX(Options!$C$2:$C$55,MATCH("yesno|"&'Raw IDs'!P11,Options!$D$2:$D$55,0)),"Not set ("&'Raw IDs'!P11&")")) -> No | S11: =IF('Raw IDs'!Q11="","Not answered",IFERROR(INDEX(Options!$C$2:$C$55,MATCH("yesno|"&'Raw IDs'!Q11,Options!$D$2:$D$55,0)),"Not set ("&'Raw IDs'!Q11&")")) -> Yes | T11: =IF('Raw IDs'!R11="","Not answered",IFERROR(INDEX(Options!$C$2:$C$55,MATCH("yesno|"&'Raw IDs'!R11,Options!$D$2:$D$55,0)),"Not set ("&'Raw IDs'!R11&")")) -> No | U11: =IF('Raw IDs'!S11="","Not answered",IFERROR(INDEX(Options!$C$2:$C$55,MATCH("seriousness|"&'Raw IDs'!S11,Options!$D$2:$D$55,0)),"Not set ("&'Raw IDs'!S11&")")) -> 3 | V11: ='Raw IDs'!T11 -> 2025-08-01
A12: ='Raw IDs'!A12 -> m11 | B12: =INDEX('ID key'!$C$2:$C$13,MATCH($A12,'ID key'!$A$2:$A$13,0))&" "&INDEX('ID key'!$D$2:$D$13,MATCH($A12,'ID key'!$A$2:$A$13,0)) -> Maryna Tykhonenko | C12: =IFERROR(INDEX('Member goals'!$E$2:$E$26,MATCH($A12&"|1",'Member goals'!$G$2:$G$26,0)),"Not provided") -> Not provided | D12: =IF('Raw IDs'!B12="","Not answered",IFERROR(INDEX(Options!$C$2:$C$55,MATCH("freq|"&'Raw IDs'!B12,Options!$D$2:$D$55,0)),"Not set ("&'Raw IDs'!B12&")")) -> Never | E12: =IF('Raw IDs'!C12="","Not answered",IFERROR(INDEX(Options!$C$2:$C$55,MATCH("time|"&'Raw IDs'!C12,Options!$D$2:$D$55,0)),"Not set ("&'Raw IDs'!C12&")")) -> Less than a year | F12: =IF('Raw IDs'!D12="","Not answered",IFERROR(INDEX(Options!$C$2:$C$55,MATCH("smoke|"&'Raw IDs'!D12,Options!$D$2:$D$55,0)),"Not set ("&'Raw IDs'!D12&")")) -> Yes | G12: =IF('Raw IDs'!E12="","Not answered",IFERROR(INDEX(Options!$C$2:$C$55,MATCH("alcohol|"&'Raw IDs'!E12,Options!$D$2:$D$55,0)),"Not set ("&'Raw IDs'!E12&")")) -> Occasionally | H12: =IF('Raw IDs'!F12="","Not answered",IFERROR(INDEX(Options!$C$2:$C$55,MATCH("work|"&'Raw IDs'!F12,Options!$D$2:$D$55,0)),"Not set ("&'Raw IDs'!F12&")")) -> Not set (0) | I12: =IF('Raw IDs'!G12="","Not answered",'Raw IDs'!G12) -> Not answered | J12: =IF('Raw IDs'!H12="","Not answered",IFERROR(INDEX(Options!$C$2:$C$55,MATCH("stress|"&'Raw IDs'!H12,Options!$D$2:$D$55,0)),"Not set ("&'Raw IDs'!H12&")")) -> High | K12: =IF('Raw IDs'!I12="","Not answered",IFERROR(INDEX(Options!$C$2:$C$55,MATCH("sleep|"&'Raw IDs'!I12,Options!$D$2:$D$55,0)),"Not set ("&'Raw IDs'!I12&")")) -> 6 or less | L12: =IF('Raw IDs'!J12="","Not answered",IFERROR(INDEX(Options!$C$2:$C$55,MATCH("diet|"&'Raw IDs'!J12,Options!$D$2:$D$55,0)),"Not set ("&'Raw IDs'!J12&")")) -> Balanced | M12: =IF('Raw IDs'!K12="","Not answered",IF('Raw IDs'!K12=0,"Not set (0)",'Raw IDs'!K12)) -> 2 | N12: =IF('Raw IDs'!L12="","Not answered",IFERROR(INDEX(Options!$C$2:$C$55,MATCH("home|"&'Raw IDs'!L12,Options!$D$2:$D$55,0)),"Not set ("&'Raw IDs'!L12&")")) -> Not answered | O12: =IF('Raw IDs'!M12="","Not answered",IFERROR(INDEX(Options!$C$2:$C$55,MATCH("takeout|"&'Raw IDs'!M12,Options!$D$2:$D$55,0)),"Not set ("&'Raw IDs'!M12&")")) -> Not answered | P12: =IF('Raw IDs'!N12="","Not answered",IFERROR(INDEX(Options!$C$2:$C$55,MATCH("yesno|"&'Raw IDs'!N12,Options!$D$2:$D$55,0)),"Not set ("&'Raw IDs'!N12&")")) -> No | Q12: =IF('Raw IDs'!O12="","Not answered",IFERROR(INDEX(Options!$C$2:$C$55,MATCH("yesno|"&'Raw IDs'!O12,Options!$D$2:$D$55,0)),"Not set ("&'Raw IDs'!O12&")")) -> No | R12: =IF('Raw IDs'!P12="","Not answered",IFERROR(INDEX(Options!$C$2:$C$55,MATCH("yesno|"&'Raw IDs'!P12,Options!$D$2:$D$55,0)),"Not set ("&'Raw IDs'!P12&")")) -> No | S12: =IF('Raw IDs'!Q12="","Not answered",IFERROR(INDEX(Options!$C$2:$C$55,MATCH("yesno|"&'Raw IDs'!Q12,Options!$D$2:$D$55,0)),"Not set ("&'Raw IDs'!Q12&")")) -> Yes | T12: =IF('Raw IDs'!R12="","Not answered",IFERROR(INDEX(Options!$C$2:$C$55,MATCH("yesno|"&'Raw IDs'!R12,Options!$D$2:$D$55,0)),"Not set ("&'Raw IDs'!R12&")")) -> Yes | U12: =IF('Raw IDs'!S12="","Not answered",IFERROR(INDEX(Options!$C$2:$C$55,MATCH("seriousness|"&'Raw IDs'!S12,Options!$D$2:$D$55,0)),"Not set ("&'Raw IDs'!S12&")")) -> Motivated | V12: ='Raw IDs'!T12 -> 2025-08-03
A13: ='Raw IDs'!A13 -> m12 | B13: =INDEX('ID key'!$C$2:$C$13,MATCH($A13,'ID key'!$A$2:$A$13,0))&" "&INDEX('ID key'!$D$2:$D$13,MATCH($A13,'ID key'!$A$2:$A$13,0)) -> Ozlem Koroglu | C13: =IFERROR(INDEX('Member goals'!$E$2:$E$26,MATCH($A13&"|1",'Member goals'!$G$2:$G$26,0)),"Not provided") -> Not provided | D13: =IF('Raw IDs'!B13="","Not answered",IFERROR(INDEX(Options!$C$2:$C$55,MATCH("freq|"&'Raw IDs'!B13,Options!$D$2:$D$55,0)),"Not set ("&'Raw IDs'!B13&")")) -> 3-4 times / week | E13: =IF('Raw IDs'!C13="","Not answered",IFERROR(INDEX(Options!$C$2:$C$55,MATCH("time|"&'Raw IDs'!C13,Options!$D$2:$D$55,0)),"Not set ("&'Raw IDs'!C13&")")) -> Less than a year | F13: =IF('Raw IDs'!D13="","Not answered",IFERROR(INDEX(Options!$C$2:$C$55,MATCH("smoke|"&'Raw IDs'!D13,Options!$D$2:$D$55,0)),"Not set ("&'Raw IDs'!D13&")")) -> Social / Occasional | G13: =IF('Raw IDs'!E13="","Not answered",IFERROR(INDEX(Options!$C$2:$C$55,MATCH("alcohol|"&'Raw IDs'!E13,Options!$D$2:$D$55,0)),"Not set ("&'Raw IDs'!E13&")")) -> Occasionally | H13: =IF('Raw IDs'!F13="","Not answered",IFERROR(INDEX(Options!$C$2:$C$55,MATCH("work|"&'Raw IDs'!F13,Options!$D$2:$D$55,0)),"Not set ("&'Raw IDs'!F13&")")) -> Not set (0) | I13: =IF('Raw IDs'!G13="","Not answered",'Raw IDs'!G13) -> Not answered | J13: =IF('Raw IDs'!H13="","Not answered",IFERROR(INDEX(Options!$C$2:$C$55,MATCH("stress|"&'Raw IDs'!H13,Options!$D$2:$D$55,0)),"Not set ("&'Raw IDs'!H13&")")) -> Manageable | K13: =IF('Raw IDs'!I13="","Not answered",IFERROR(INDEX(Options!$C$2:$C$55,MATCH("sleep|"&'Raw IDs'!I13,Options!$D$2:$D$55,0)),"Not set ("&'Raw IDs'!I13&")")) -> 7 or more | L13: =IF('Raw IDs'!J13="","Not answered",IFERROR(INDEX(Options!$C$2:$C$55,MATCH("diet|"&'Raw IDs'!J13,Options!$D$2:$D$55,0)),"Not set ("&'Raw IDs'!J13&")")) -> Balanced | M13: =IF('Raw IDs'!K13="","Not answered",IF('Raw IDs'!K13=0,"Not set (0)",'Raw IDs'!K13)) -> 2 | N13: =IF('Raw IDs'!L13="","Not answered",IFERROR(INDEX(Options!$C$2:$C$55,MATCH("home|"&'Raw IDs'!L13,Options!$D$2:$D$55,0)),"Not set ("&'Raw IDs'!L13&")")) -> Not answered | O13: =IF('Raw IDs'!M13="","Not answered",IFERROR(INDEX(Options!$C$2:$C$55,MATCH("takeout|"&'Raw IDs'!M13,Options!$D$2:$D$55,0)),"Not set ("&'Raw IDs'!M13&")")) -> Not answered | P13: =IF('Raw IDs'!N13="","Not answered",IFERROR(INDEX(Options!$C$2:$C$55,MATCH("yesno|"&'Raw IDs'!N13,Options!$D$2:$D$55,0)),"Not set ("&'Raw IDs'!N13&")")) -> No | Q13: =IF('Raw IDs'!O13="","Not answered",IFERROR(INDEX(Options!$C$2:$C$55,MATCH("yesno|"&'Raw IDs'!O13,Options!$D$2:$D$55,0)),"Not set ("&'Raw IDs'!O13&")")) -> No | R13: =IF('Raw IDs'!P13="","Not answered",IFERROR(INDEX(Options!$C$2:$C$55,MATCH("yesno|"&'Raw IDs'!P13,Options!$D$2:$D$55,0)),"Not set ("&'Raw IDs'!P13&")")) -> No | S13: =IF('Raw IDs'!Q13="","Not answered",IFERROR(INDEX(Options!$C$2:$C$55,MATCH("yesno|"&'Raw IDs'!Q13,Options!$D$2:$D$55,0)),"Not set ("&'Raw IDs'!Q13&")")) -> Yes | T13: =IF('Raw IDs'!R13="","Not answered",IFERROR(INDEX(Options!$C$2:$C$55,MATCH("yesno|"&'Raw IDs'!R13,Options!$D$2:$D$55,0)),"Not set ("&'Raw IDs'!R13&")")) -> No | U13: =IF('Raw IDs'!S13="","Not answered",IFERROR(INDEX(Options!$C$2:$C$55,MATCH("seriousness|"&'Raw IDs'!S13,Options!$D$2:$D$55,0)),"Not set ("&'Raw IDs'!S13&")")) -> 4 | V13: ='Raw IDs'!T13 -> 2025-08-03
A18: Notes
A19: Labels come from the Options tab using the IDs on the Raw IDs tab. Names come from the ID key tab.
A20: Not answered = the database value is empty (NULL). Not set (0) = the database holds 0, which matches no option.
A21: Goals, activities, health conditions and last week's attendance are not in member_details, so they are not in this workbook yet.
A22: Medication and medical treatment were left out on purpose (health data).
A23: Yellow goal cells have no goal yet because the goal rows were not available. See the Member goals tab.
A24: Sitting hours and Number of meals are numbers stored as entered. Their unit is not confirmed in the data.
A25: This workbook contains real member names. Do not paste names into model prompts. Use the Test ID instead.
A26: The Last week attendance tab holds made-up sample data for testing, not real check-ins.

Sheet Last week attendance
A1: Test ID | B1: Member name | C1: Cardio | D1: Strength | E1: Shape | F1: Strength & Conditioning | G1: Wellness | H1: Red Light Therapy | I1: Classes (excl. Red Light) | J1: Within slot caps? | K1: Stated frequency | L1: Goal used for test
A2: ='Raw IDs'!A2 -> m1 | B2: ='Wellness preferences'!B2 -> Levent Soydaner | C2: 1 | D2: 1 | E2: 1 | F2: 1 | G2: 0 | H2: 1 | I2: =SUM(C2:G2) -> 4 | J2: =IF(AND(C2<=C$15,D2<=D$15,E2<=E$15,F2<=F$15,G2<=G$15,H2<=H$15),"Yes","No") -> Yes | K2: ='Wellness preferences'!D2 -> 3-4 times / week | L2: ='Wellness preferences'!C2 -> Improve cardio performance
A3: ='Raw IDs'!A3 -> m2 | B3: ='Wellness preferences'!B3 -> Veronika Masarskaya | C3: 1 | D3: 0 | E3: 0 | F3: 0 | G3: 1 | H3: 0 | I3: =SUM(C3:G3) -> 2 | J3: =IF(AND(C3<=C$15,D3<=D$15,E3<=E$15,F3<=F$15,G3<=G$15,H3<=H$15),"Yes","No") -> Yes | K3: ='Wellness preferences'!D3 -> 1-2 times / week | L3: ='Wellness preferences'!C3 -> Weight loss
A4: ='Raw IDs'!A4 -> m3 | B4: ='Wellness preferences'!B4 -> Elen Kost | C4: 0 | D4: 1 | E4: 1 | F4: 1 | G4: 0 | H4: 2 | I4: =SUM(C4:G4) -> 3 | J4: =IF(AND(C4<=C$15,D4<=D$15,E4<=E$15,F4<=F$15,G4<=G$15,H4<=H$15),"Yes","No") -> Yes | K4: ='Wellness preferences'!D4 -> 3-4 times / week | L4: ='Wellness preferences'!C4 -> Muscle tone
A5: ='Raw IDs'!A5 -> m4 | B5: ='Wellness preferences'!B5 -> Emma Arlemark | C5: 0 | D5: 0 | E5: 1 | F5: 0 | G5: 0 | H5: 1 | I5: =SUM(C5:G5) -> 1 | J5: =IF(AND(C5<=C$15,D5<=D$15,E5<=E$15,F5<=F$15,G5<=G$15,H5<=H$15),"Yes","No") -> Yes | K5: ='Wellness preferences'!D5 -> 1-2 times / week | L5: ='Wellness preferences'!C5 -> Weight loss
A6: ='Raw IDs'!A6 -> m5 | B6: ='Wellness preferences'!B6 -> Ria Juma | C6: 1 | D6: 1 | E6: 0 | F6: 1 | G6: 1 | H6: 0 | I6: =SUM(C6:G6) -> 4 | J6: =IF(AND(C6<=C$15,D6<=D$15,E6<=E$15,F6<=F$15,G6<=G$15,H6<=H$15),"Yes","No") -> Yes | K6: ='Wellness preferences'!D6 -> 3-4 times / week | L6: ='Wellness preferences'!C6 -> Build strength
A7: ='Raw IDs'!A7 -> m6 | B7: ='Wellness preferences'!B7 -> Maria Costanzo | C7: 0 | D7: 2 | E7: 1 | F7: 0 | G7: 1 | H7: 1 | I7: =SUM(C7:G7) -> 4 | J7: =IF(AND(C7<=C$15,D7<=D$15,E7<=E$15,F7<=F$15,G7<=G$15,H7<=H$15),"Yes","No") -> Yes | K7: ='Wellness preferences'!D7 -> 3-4 times / week | L7: ='Wellness preferences'!C7 -> Muscle tone
A8: ='Raw IDs'!A8 -> m7 | B8: ='Wellness preferences'!B8 -> Vinay Parmar | C8: 1 | D8: 2 | E8: 1 | F8: 1 | G8: 0 | H8: 3 | I8: =SUM(C8:G8) -> 5 | J8: =IF(AND(C8<=C$15,D8<=D$15,E8<=E$15,F8<=F$15,G8<=G$15,H8<=H$15),"Yes","No") -> Yes | K8: ='Wellness preferences'!D8 -> 5-6 times / week | L8: ='Wellness preferences'!C8 -> Weight loss
A9: ='Raw IDs'!A9 -> m8 | B9: ='Wellness preferences'!B9 -> Ruksana Hussain | C9: 1 | D9: 1 | E9: 2 | F9: 2 | G9: 0 | H9: 2 | I9: =SUM(C9:G9) -> 6 | J9: =IF(AND(C9<=C$15,D9<=D$15,E9<=E$15,F9<=F$15,G9<=G$15,H9<=H$15),"Yes","No") -> Yes | K9: ='Wellness preferences'!D9 -> 5-6 times / week | L9: ='Wellness preferences'!C9 -> Weight loss
A10: ='Raw IDs'!A10 -> m9 | B10: ='Wellness preferences'!B10 -> Asif Khokhar | C10: 1 | D10: 0 | E10: 0 | F10: 1 | G10: 0 | H10: 0 | I10: =SUM(C10:G10) -> 2 | J10: =IF(AND(C10<=C$15,D10<=D$15,E10<=E$15,F10<=F$15,G10<=G$15,H10<=H$15),"Yes","No") -> Yes | K10: ='Wellness preferences'!D10 -> 1-2 times / week | L10: ='Wellness preferences'!C10 -> Not provided
A11: ='Raw IDs'!A11 -> m10 | B11: ='Wellness preferences'!B11 -> Sadaf Hameed | C11: 0 | D11: 1 | E11: 0 | F11: 0 | G11: 1 | H11: 1 | I11: =SUM(C11:G11) -> 2 | J11: =IF(AND(C11<=C$15,D11<=D$15,E11<=E$15,F11<=F$15,G11<=G$15,H11<=H$15),"Yes","No") -> Yes | K11: ='Wellness preferences'!D11 -> 1-2 times / week | L11: ='Wellness preferences'!C11 -> Not provided
A12: ='Raw IDs'!A12 -> m11 | B12: ='Wellness preferences'!B12 -> Maryna Tykhonenko | C12: 0 | D12: 0 | E12: 0 | F12: 0 | G12: 0 | H12: 0 | I12: =SUM(C12:G12) -> 0 | J12: =IF(AND(C12<=C$15,D12<=D$15,E12<=E$15,F12<=F$15,G12<=G$15,H12<=H$15),"Yes","No") -> Yes | K12: ='Wellness preferences'!D12 -> Never | L12: ='Wellness preferences'!C12 -> Not provided
A13: ='Raw IDs'!A13 -> m12 | B13: ='Wellness preferences'!B13 -> Ozlem Koroglu | C13: 1 | D13: 0 | E13: 2 | F13: 1 | G13: 0 | H13: 0 | I13: =SUM(C13:G13) -> 4 | J13: =IF(AND(C13<=C$15,D13<=D$15,E13<=E$15,F13<=F$15,G13<=G$15,H13<=H$15),"Yes","No") -> Yes | K13: ='Wellness preferences'!D13 -> 3-4 times / week | L13: ='Wellness preferences'!C13 -> Not provided
A15: Slot cap | C15: 1 | D15: 2 | E15: 2 | F15: 2 | G15: 2 | H15: 5
A17: SAMPLE DATA: these attendance numbers are made up for testing. They are not real check-ins.
A18: Counts are sessions attended last week per category. Each member's total roughly follows their stated activity frequency. Red Light Therapy is recovery and is not counted in the class total.
A19: Slot caps come from the class catalog used by the planner (editable above). Blue = values you can change.

Sheet Prompt input
A1: Test ID | B1: Gender | C1: Age | D1: Fitness goal | E1: Current activities | F1: Exercise frequency | G1: Active | H1: Conditions | I1: Medications | J1: Smoker | K1: Alcohol consumption | L1: Medical treatment | M1: Cardio | N1: Strength | O1: Shape | P1: Strength & Conditioning | Q1: Wellness | R1: Red Light Therapy | S1: Full prompt (formula) | T1: Est. input tokens (characters / 4) | U1: Optimized prompt (formula) | V1: Optimized est. input tokens (characters / 4) | W1: Tokens saved vs original (estimate)
A2: ='Raw IDs'!A2 -> m1 | B2: Female | C2: 42 | D2: ='Wellness preferences'!C2 -> Improve cardio performance | F2: ='Wellness preferences'!D2 -> 3-4 times / week | G2: ='Wellness preferences'!E2 -> 1-3 years | J2: ='Wellness preferences'!F2 -> No | K2: ='Wellness preferences'!G2 -> Occasionally | M2: ='Last week attendance'!C2 -> 1 | N2: ='Last week attendance'!D2 -> 1 | O2: ='Last week attendance'!E2 -> 1 | P2: ='Last week attendance'!F2 -> 1 | Q2: ='Last week attendance'!G2 -> 0 | R2: ='Last week attendance'!H2 -> 1 | S2: ='Prompt template'!$A$2&CHAR(10)&CHAR(10)&"[MEMBER'S PROFILE]"&CHAR(10)&"Gender: "&IF(B2="","Not provided",B2)&CHAR(10)&"Age: "&IF(C2="","Not provided",C2)&CHAR(10)&CHAR(10)&"*MEMBER'S WELLNESS QUESTIONAIRE DATA*"&CHAR(10)&CHAR(10)&"Fitness goal: "&IF(D2="","Not provided",D2)&CHAR(10)&CHAR(10)&"Current activities: "&IF(E2="","Not provided",E2)&CHAR(10)&"Exercise frequency: "&IF(F2="","Not provided",F2)&CHAR(10)&"Active: "&IF(G2="","Not provided",G2)&CHAR(10)&"Conditions: "&IF(H2="","Not provided",H2)&CHAR(10)&"Medications: "&IF(I2="","Not provided",I2)&CHAR(10)&"Smoker: "&IF(J2="","Not provided",J2)&CHAR(10)&"Alcohol consumption: "&IF(K2="","Not provided",K2)&CHAR(10)&"Medical treatment: "&IF(L2="","Not provided",L2)&CHAR(10)&CHAR(10)&"*LAST WEEKS SESSIONS*"&CHAR(10)&"Cardio="&M2&CHAR(10)&"Strength="&N2&CHAR(10)&"Shape="&O2&CHAR(10)&"Strength & Conditioning="&P2&CHAR(10)&"Wellness="&Q2&CHAR(10)&"Red Light Therapy="&R2 -> [INSTRUCTIONS] You are a seasoned fitness consultant. You will take the following member profile and suggest their booking session goals for the next coming week and suggest how many sessions from the [CONTEXT] they need to book in order to progress in their stated fitness goal. Note that some Classes have max 1/2 sessions slots per week. [CONTEXT] Cardio Sessions (1 slot/week) - 50min Session. feature powerful exercise sequences performed at speed and combining bodyweight, freestanding equipment and machines. Work more, rest less, pushing your calorie burn to the max. Strength (2 slot/week) - 50min Session. Utilizes resistance training, time under tension and functional drop sets to develop your muscle density and mobility. Perform controlled exercises and focus on technique and expanding your range of movement. Shape (2 slot/week) - 50min Session. Combines cardio and strength training through a mix of controlled, consistent high tempo movements. Build muscular endurance, reduce body imbalance and burn calories, while also lighting up your cardiovascular system. Strength & Conditioning (2 slot/week) - 50min Session. Dynamic sequences combining power, endurance, and functional performance. Expect full body movement patterns and conditioning intervals that challenge your strength, coordination, and stamina while improving overall physical capacity. Wellness (2 slot/week) - 30min/50min Sessions. Designed to enhance mobility, flexibility, and overall wellbeing. Slow the pace, reconnect with your body, and restore balance through mindful movement and guided mobility work. Red Light Therapy (5 slots/week) - 10min Sessions. Boost recovery, improve skin health, and reduce inflammation with our red light therapy sessions. A quick and effective way to help your body recharge and heal faster. Pre or post workout has equal benefits. [MEMBER'S PROFILE] Gender: Female Age: 42 *MEMBER'S WELLNESS QUESTIONAIRE DATA* Fitness goal: Improve cardio performance Current activities: Not provided Exercise frequency: 3-4 times / week Active: 1-3 years Conditions: Not provided Medications: Not provided Smoker: No Alcohol consumption: Occasionally Medical treatment: Not provided *LAST WEEKS SESSIONS* Cardio=1 Strength=1 Shape=1 Strength & Conditioning=1 Wellness=0 Red Light Therapy=1 | T2: =ROUND(LEN(S2)/4,0) -> 577 | U2: ='Prompt template (optimized)'!$A$2&CHAR(10)&CHAR(10)&"Member:"&IF(AND(B2="",C2=""),"",CHAR(10)&"Profile: "&_xlfn.TEXTJOIN(", ",TRUE(),B2,C2))&IF(OR(D2="",LEFT(D2,3)="Not"),"",CHAR(10)&"Goal: "&D2)&IF(OR(E2="",LEFT(E2,3)="Not"),"",CHAR(10)&"Activities: "&E2)&IF(OR(F2="",LEFT(F2,3)="Not"),"",CHAR(10)&"Exercise frequency: "&F2)&IF(OR(G2="",LEFT(G2,3)="Not"),"",CHAR(10)&"Training history: "&G2)&IF(OR(H2="",LEFT(H2,3)="Not"),"",CHAR(10)&"Conditions: "&H2)&IF(OR(I2="",LEFT(I2,3)="Not"),"",CHAR(10)&"Medications: "&I2)&IF(OR(L2="",LEFT(L2,3)="Not"),"",CHAR(10)&"Medical treatment: "&L2)&IF(OR(J2="",LEFT(J2,3)="Not"),"",CHAR(10)&"Smoker: "&J2)&IF(OR(K2="",LEFT(K2,3)="Not"),"",CHAR(10)&"Alcohol: "&K2)&CHAR(10)&"Last week: "&"Cardio="&M2&", "&"Strength="&N2&", "&"Shape="&O2&", "&"Strength & Conditioning="&P2&", "&"Wellness="&Q2&", "&"Red Light Therapy="&R2&CHAR(10)&CHAR(10)&'Prompt template (optimized)'!$A$5 -> You are a fitness consultant. Plan the member's class bookings for next week so they progress toward their stated goal. Weekly slot caps (never exceed): Cardio 1, Strength 2, Shape 2, Strength & Conditioning 2, Wellness 2, Red Light Therapy 5. Classes: - Cardio: high-intensity intervals (bodyweight, equipment, machines); maximum calorie burn. - Strength: resistance training and time under tension; muscle density, mobility, technique. - Shape: high-tempo cardio and strength mix; muscular endurance, body balance, calorie burn. - Strength & Conditioning: power, endurance and functional full-body conditioning; stamina, coordination. - Wellness: mobility, flexibility and mindful recovery. - Red Light Therapy: 10-minute recovery session, before or after a workout; recovery, skin, inflammation. Rules: - Use whole numbers from 0 up to each cap. - Use last week's sessions as the baseline and progress toward the goal without a sudden jump. - Keep the total realistic for the member's exercise frequency, health and recovery. Member: Profile: Female, 42 Goal: Improve cardio performance Exercise frequency: 3-4 times / week Training history: 1-3 years Smoker: No Alcohol: Occasionally Last week: Cardio=1, Strength=1, Shape=1, Strength & Conditioning=1, Wellness=0, Red Light Therapy=1 Answer with JSON only, no other text: {"Cardio":#,"Strength":#,"Shape":#,"Strength & Conditioning":#,"Wellness":#,"Red Light Therapy":#} | V2: =ROUND(LEN(U2)/4,0) -> 358 | W2: =T2-V2 -> 219
A3: ='Raw IDs'!A3 -> m2 | B3: Female | C3: 36 | D3: ='Wellness preferences'!C3 -> Weight loss | F3: ='Wellness preferences'!D3 -> 1-2 times / week | G3: ='Wellness preferences'!E3 -> 3+ years | J3: ='Wellness preferences'!F3 -> No | K3: ='Wellness preferences'!G3 -> Never | M3: ='Last week attendance'!C3 -> 1 | N3: ='Last week attendance'!D3 -> 0 | O3: ='Last week attendance'!E3 -> 0 | P3: ='Last week attendance'!F3 -> 0 | Q3: ='Last week attendance'!G3 -> 1 | R3: ='Last week attendance'!H3 -> 0 | S3: ='Prompt template'!$A$2&CHAR(10)&CHAR(10)&"[MEMBER'S PROFILE]"&CHAR(10)&"Gender: "&IF(B3="","Not provided",B3)&CHAR(10)&"Age: "&IF(C3="","Not provided",C3)&CHAR(10)&CHAR(10)&"*MEMBER'S WELLNESS QUESTIONAIRE DATA*"&CHAR(10)&CHAR(10)&"Fitness goal: "&IF(D3="","Not provided",D3)&CHAR(10)&CHAR(10)&"Current activities: "&IF(E3="","Not provided",E3)&CHAR(10)&"Exercise frequency: "&IF(F3="","Not provided",F3)&CHAR(10)&"Active: "&IF(G3="","Not provided",G3)&CHAR(10)&"Conditions: "&IF(H3="","Not provided",H3)&CHAR(10)&"Medications: "&IF(I3="","Not provided",I3)&CHAR(10)&"Smoker: "&IF(J3="","Not provided",J3)&CHAR(10)&"Alcohol consumption: "&IF(K3="","Not provided",K3)&CHAR(10)&"Medical treatment: "&IF(L3="","Not provided",L3)&CHAR(10)&CHAR(10)&"*LAST WEEKS SESSIONS*"&CHAR(10)&"Cardio="&M3&CHAR(10)&"Strength="&N3&CHAR(10)&"Shape="&O3&CHAR(10)&"Strength & Conditioning="&P3&CHAR(10)&"Wellness="&Q3&CHAR(10)&"Red Light Therapy="&R3 -> [INSTRUCTIONS] You are a seasoned fitness consultant. You will take the following member profile and suggest their booking session goals for the next coming week and suggest how many sessions from the [CONTEXT] they need to book in order to progress in their stated fitness goal. Note that some Classes have max 1/2 sessions slots per week. [CONTEXT] Cardio Sessions (1 slot/week) - 50min Session. feature powerful exercise sequences performed at speed and combining bodyweight, freestanding equipment and machines. Work more, rest less, pushing your calorie burn to the max. Strength (2 slot/week) - 50min Session. Utilizes resistance training, time under tension and functional drop sets to develop your muscle density and mobility. Perform controlled exercises and focus on technique and expanding your range of movement. Shape (2 slot/week) - 50min Session. Combines cardio and strength training through a mix of controlled, consistent high tempo movements. Build muscular endurance, reduce body imbalance and burn calories, while also lighting up your cardiovascular system. Strength & Conditioning (2 slot/week) - 50min Session. Dynamic sequences combining power, endurance, and functional performance. Expect full body movement patterns and conditioning intervals that challenge your strength, coordination, and stamina while improving overall physical capacity. Wellness (2 slot/week) - 30min/50min Sessions. Designed to enhance mobility, flexibility, and overall wellbeing. Slow the pace, reconnect with your body, and restore balance through mindful movement and guided mobility work. Red Light Therapy (5 slots/week) - 10min Sessions. Boost recovery, improve skin health, and reduce inflammation with our red light therapy sessions. A quick and effective way to help your body recharge and heal faster. Pre or post workout has equal benefits. [MEMBER'S PROFILE] Gender: Female Age: 36 *MEMBER'S WELLNESS QUESTIONAIRE DATA* Fitness goal: Weight loss Current activities: Not provided Exercise frequency: 1-2 times / week Active: 3+ years Conditions: Not provided Medications: Not provided Smoker: No Alcohol consumption: Never Medical treatment: Not provided *LAST WEEKS SESSIONS* Cardio=1 Strength=0 Shape=0 Strength & Conditioning=0 Wellness=1 Red Light Therapy=0 | T3: =ROUND(LEN(S3)/4,0) -> 571 | U3: ='Prompt template (optimized)'!$A$2&CHAR(10)&CHAR(10)&"Member:"&IF(AND(B3="",C3=""),"",CHAR(10)&"Profile: "&_xlfn.TEXTJOIN(", ",TRUE(),B3,C3))&IF(OR(D3="",LEFT(D3,3)="Not"),"",CHAR(10)&"Goal: "&D3)&IF(OR(E3="",LEFT(E3,3)="Not"),"",CHAR(10)&"Activities: "&E3)&IF(OR(F3="",LEFT(F3,3)="Not"),"",CHAR(10)&"Exercise frequency: "&F3)&IF(OR(G3="",LEFT(G3,3)="Not"),"",CHAR(10)&"Training history: "&G3)&IF(OR(H3="",LEFT(H3,3)="Not"),"",CHAR(10)&"Conditions: "&H3)&IF(OR(I3="",LEFT(I3,3)="Not"),"",CHAR(10)&"Medications: "&I3)&IF(OR(L3="",LEFT(L3,3)="Not"),"",CHAR(10)&"Medical treatment: "&L3)&IF(OR(J3="",LEFT(J3,3)="Not"),"",CHAR(10)&"Smoker: "&J3)&IF(OR(K3="",LEFT(K3,3)="Not"),"",CHAR(10)&"Alcohol: "&K3)&CHAR(10)&"Last week: "&"Cardio="&M3&", "&"Strength="&N3&", "&"Shape="&O3&", "&"Strength & Conditioning="&P3&", "&"Wellness="&Q3&", "&"Red Light Therapy="&R3&CHAR(10)&CHAR(10)&'Prompt template (optimized)'!$A$5 -> You are a fitness consultant. Plan the member's class bookings for next week so they progress toward their stated goal. Weekly slot caps (never exceed): Cardio 1, Strength 2, Shape 2, Strength & Conditioning 2, Wellness 2, Red Light Therapy 5. Classes: - Cardio: high-intensity intervals (bodyweight, equipment, machines); maximum calorie burn. - Strength: resistance training and time under tension; muscle density, mobility, technique. - Shape: high-tempo cardio and strength mix; muscular endurance, body balance, calorie burn. - Strength & Conditioning: power, endurance and functional full-body conditioning; stamina, coordination. - Wellness: mobility, flexibility and mindful recovery. - Red Light Therapy: 10-minute recovery session, before or after a workout; recovery, skin, inflammation. Rules: - Use whole numbers from 0 up to each cap. - Use last week's sessions as the baseline and progress toward the goal without a sudden jump. - Keep the total realistic for the member's exercise frequency, health and recovery. Member: Profile: Female, 36 Goal: Weight loss Exercise frequency: 1-2 times / week Training history: 3+ years Smoker: No Alcohol: Never Last week: Cardio=1, Strength=0, Shape=0, Strength & Conditioning=0, Wellness=1, Red Light Therapy=0 Answer with JSON only, no other text: {"Cardio":#,"Strength":#,"Shape":#,"Strength & Conditioning":#,"Wellness":#,"Red Light Therapy":#} | V3: =ROUND(LEN(U3)/4,0) -> 352 | W3: =T3-V3 -> 219
